import { describe, expect, it, vi } from 'vitest';
import { render, screen, fireEvent } from '@testing-library/react';

import { ErrorBoundary } from '@/app/(sidebar-layout)/(container)/library/components/ErrorBoundary';

// Component that throws an error
const ThrowError = ({ shouldThrow }: { shouldThrow: boolean }) => {
  if (shouldThrow) {
    throw new Error('Test error message');
  }
  return <div>No error</div>;
};

describe('ErrorBoundary', () => {
  // Suppress console.error for these tests
  const originalError = console.error;
  beforeAll(() => {
    console.error = vi.fn();
  });

  afterAll(() => {
    console.error = originalError;
  });

  it('should render children when there is no error', () => {
    render(
      <ErrorBoundary>
        <div>Test content</div>
      </ErrorBoundary>
    );

    expect(screen.getByText('Test content')).toBeInTheDocument();
  });

  it('should render error UI when child component throws', () => {
    render(
      <ErrorBoundary>
        <ThrowError shouldThrow={true} />
      </ErrorBoundary>
    );

    expect(screen.getByText('Something went wrong')).toBeInTheDocument();
    expect(screen.getByText('Test error message')).toBeInTheDocument();
    expect(screen.getByRole('button', { name: 'Try Again' })).toBeInTheDocument();
  });

  it('should render custom fallback when provided', () => {
    const fallback = <div>Custom error message</div>;

    render(
      <ErrorBoundary fallback={fallback}>
        <ThrowError shouldThrow={true} />
      </ErrorBoundary>
    );

    expect(screen.getByText('Custom error message')).toBeInTheDocument();
    expect(screen.queryByText('Something went wrong')).not.toBeInTheDocument();
  });

  it('should reset error state when Try Again is clicked', () => {
    render(
      <ErrorBoundary>
        <ThrowError shouldThrow={true} />
      </ErrorBoundary>
    );

    // Error should be displayed
    expect(screen.getByText('Something went wrong')).toBeInTheDocument();

    // Click Try Again - this should reset the error boundary state
    fireEvent.click(screen.getByRole('button', { name: 'Try Again' }));

    // After reset, the error boundary tries to render its children again
    // Since the child still throws, it will show the error again
    // This is the expected behavior - reset only clears the state,
    // it doesn't prevent the child from throwing again
    expect(screen.getByText('Something went wrong')).toBeInTheDocument();
  });

  it('should handle errors without messages', () => {
    const ThrowEmptyError = () => {
      throw new Error();
    };

    render(
      <ErrorBoundary>
        <ThrowEmptyError />
      </ErrorBoundary>
    );

    expect(screen.getByText('Something went wrong')).toBeInTheDocument();
    expect(screen.getByText('An unexpected error occurred while rendering this component.')).toBeInTheDocument();
  });

  it('should log errors to console', () => {
    const consoleErrorSpy = vi.spyOn(console, 'error');

    render(
      <ErrorBoundary>
        <ThrowError shouldThrow={true} />
      </ErrorBoundary>
    );

    expect(consoleErrorSpy).toHaveBeenCalledWith(
      'Uncaught error in ErrorBoundary:',
      expect.any(Error),
      expect.any(Object)
    );
  });
});